Workbook

Sheet CLIENTS (3)
A1: ID_Client | B1: Province_Client | C1: Anciennete_Mois | D1: Type_Forfait | E1: Duree_Cumulee_Panne_Min | F1: Facture_Mensuelle | G1: Plaintes_Service_Client | H1: Anciennete_Mois - Copier | I1: ans | J1: min | K1: Remise client | L1: Perte financiere | M1: Type client
A2: CLI-01147 | B2: Ituri | C2: 29 | D2: Premium 5G 150Go | E2: 214 | F2: 74.7 | G2: 3 | H2: 29 | I2: 2 | J2: 4 | K2: =IF(OR(CLIENTS__3[[#This Row],[Duree_Cumulee_Panne_Min]]>=240,CLIENTS__3[[#This Row],[Plaintes_Service_Client]]>2),"45%",IF(CLIENTS__3[[#This Row],[Anciennete_Mois]]>=60,"10%",IF(CLIENTS__3[[#This Row],[Type_Forfait]]="Premium 5G 150 Go","70%","0%"))) -> 45% | L2: =(CLIENTS__3[[#This Row],[Facture_Mensuelle]]*CLIENTS__3[[#This Row],[ Remise client]]) -> 33.615 | M2: =IF(CLIENTS__3[[#This Row],[Facture_Mensuelle]]<80,"B2B","B2C") -> B2B
A3: CLI-00894 | B3: Tshuapa | C3: 63 | D3: Pro Monde | E3: 205 | F3: 89.19 | G3: 0 | H3: 63 | I3: 5 | J3: 3 | K3: =IF(OR(CLIENTS__3[[#This Row],[Duree_Cumulee_Panne_Min]]>=240,CLIENTS__3[[#This Row],[Plaintes_Service_Client]]>2),"45%",IF(CLIENTS__3[[#This Row],[Anciennete_Mois]]>=60,"10%",IF(CLIENTS__3[[#This Row],[Type_Forfait]]="Premium 5G 150 Go","70%","0%"))) -> 10% | L3: =(CLIENTS__3[[#This Row],[Facture_Mensuelle]]*CLIENTS__3[[#This Row],[ Remise client]]) -> 8.919 | M3: =IF(CLIENTS__3[[#This Row],[Facture_Mensuelle]]<80,"B2B","B2C") -> B2C
A4: CLI-00865 | B4: Mongala | C4: 34 | D4: Pro Monde | E4: 453 | F4: 56.84 | G4: 0 | H4: 34 | I4: 3 | J4: 8 | K4: =IF(OR(CLIENTS__3[[#This Row],[Duree_Cumulee_Panne_Min]]>=240,CLIENTS__3[[#This Row],[Plaintes_Service_Client]]>2),"45%",IF(CLIENTS__3[[#This Row],[Anciennete_Mois]]>=60,"10%",IF(CLIENTS__3[[#This Row],[Type_Forfait]]="Premium 5G 150 Go","70%","0%"))) -> 45% | L4: =(CLIENTS__3[[#This Row],[Facture_Mensuelle]]*CLIENTS__3[[#This Row],[ Remise client]]) -> 25.578 | M4: =IF(CLIENTS__3[[#This Row],[Facture_Mensuelle]]<80,"B2B","B2C") -> B2B
A5: CLI-01325 | B5: Haut-Lomami | C5: 44 | D5: Bloqué 5Go | E5: 348 | F5: 58.67 | G5: 0 | H5: 44 | I5: 4 | J5: 6 | K5: =IF(OR(CLIENTS__3[[#This Row],[Duree_Cumulee_Panne_Min]]>=240,CLIENTS__3[[#This Row],[Plaintes_Service_Client]]>2),"45%",IF(CLIENTS__3[[#This Row],[Anciennete_Mois]]>=60,"10%",IF(CLIENTS__3[[#This Row],[Type_Forfait]]="Premium 5G 150 Go","70%","0%"))) -> 45% | L5: =(CLIENTS__3[[#This Row],[Facture_Mensuelle]]*CLIENTS__3[[#This Row],[ Remise client]]) -> 26.4015 | M5: =IF(CLIENTS__3[[#This Row],[Facture_Mensuelle]]<80,"B2B","B2C") -> B2B
A6: CLI-01855 | B6: Sud-Kivu | C6: 101 | D6: Illimité 50Go | E6: 358 | F6: 29.24 | G6: 3 | H6: 101 | I6: 8 | J6: 6 | K6: =IF(OR(CLIENTS__3[[#This Row],[Duree_Cumulee_Panne_Min]]>=240,CLIENTS__3[[#This Row],[Plaintes_Service_Client]]>2),"45%",IF(CLIENTS__3[[#This Row],[Anciennete_Mois]]>=60,"10%",IF(CLIENTS__3[[#This Row],[Type_Forfait]]="Premium 5G 150 Go","70%","0%"))) -> 45% | L6: =(CLIENTS__3[[#This Row],[Facture_Mensuelle]]*CLIENTS__3[[#This Row],[ Remise client]]) -> 13.158 | M6: =IF(CLIENTS__3[[#This Row],[Facture_Mensuelle]]<80,"B2B","B2C") -> B2B
A7: CLI-00076 | B7: Haut-Katanga | C7: 46 | D7: Premium 5G 150Go | E7: 283 | F7: 56.05 | G7: 1 | H7: 46 | I7: 4 | J7: 5 | K7: =IF(OR(CLIENTS__3[[#This Row],[Duree_Cumulee_Panne_Min]]>=240,CLIENTS__3[[#This Row],[Plaintes_Service_Client]]>2),"45%",IF(CLIENTS__3[[#This Row],[Anciennete_Mois]]>=60,"10%",IF(CLIENTS__3[[#This Row],[Type_Forfait]]="Premium 5G 150 Go","70%","0%"))) -> 45% | L7: =(CLIENTS__3[[#This Row],[Facture_Mensuelle]]*CLIENTS__3[[#This Row],[ Remise client]]) -> 25.2225 | M7: =IF(CLIENTS__3[[#This Row],[Facture_Mensuelle]]<80,"B2B","B2C") -> B2B
A8: CLI-00414 | B8: Bas-Uele | C8: 99 | D8: Premium 5G 150Go | E8: 447 | F8: 38.1 | G8: 3 | H8: 99 | I8: 8 | J8: 7 | K8: =IF(OR(CLIENTS__3[[#This Row],[Duree_Cumulee_Panne_Min]]>=240,CLIENTS__3[[#This Row],[Plaintes_Service_Client]]>2),"45%",IF(CLIENTS__3[[#This Row],[Anciennete_Mois]]>=60,"10%",IF(CLIENTS__3[[#This Row],[Type_Forfait]]="Premium 5G 150 Go","70%","0%"))) -> 45% | L8: =(CLIENTS__3[[#This Row],[Facture_Mensuelle]]*CLIENTS__3[[#This Row],[ Remise client]]) -> 17.145 | M8: =IF(CLIENTS__3[[#This Row],[Facture_Mensuelle]]<80,"B2B","B2C") -> B2B
A9: CLI-00327 | B9: Haut-Katanga | C9: 6 | D9: Illimité 50Go | E9: 155 | F9: 40.66 | G9: 1 | H9: 6 | I9: 0 | J9: 3 | K9: =IF(OR(CLIENTS__3[[#This Row],[Duree_Cumulee_Panne_Min]]>=240,CLIENTS__3[[#This Row],[Plaintes_Service_Client]]>2),"45%",IF(CLIENTS__3[[#This Row],[Anciennete_Mois]]>=60,"10%",IF(CLIENTS__3[[#This Row],[Type_Forfait]]="Premium 5G 150 Go","70%","0%"))) -> 0% | L9: =(CLIENTS__3[[#This Row],[Facture_Mensuelle]]*CLIENTS__3[[#This Row],[ Remise client]]) -> 0 | M9: =IF(CLIENTS__3[[#This Row],[Facture_Mensuelle]]<80,"B2B","B2C") -> B2B
A10: CLI-00559 | B10: Kasai | C10: 99 | D10: Bloqué 5Go | E10: 369 | F10: 67.21 | G10: 3 | H10: 99 | I10: 8 | J10: 6 | K10: =IF(OR(CLIENTS__3[[#This Row],[Duree_Cumulee_Panne_Min]]>=240,CLIENTS__3[[#This Row],[Plaintes_Service_Client]]>2),"45%",IF(CLIENTS__3[[#This Row],[Anciennete_Mois]]>=60,"10%",IF(CLIENTS__3[[#This Row],[Type_Forfait]]="Premium 5G 150 Go","70%","0%"))) -> 45% | L10: =(CLIENTS__3[[#This Row],[Facture_Mensuelle]]*CLIENTS__3[[#This Row],[ Remise client]]) -> 30.2445 | M10: =IF(CLIENTS__3[[#This Row],[Facture_Mensuelle]]<80,"B2B","B2C") -> B2B
A11: CLI-00280 | B11: Sud-Ubangi | C11: 113 | D11: Illimité 50Go | E11: 380 | F11: 12.11 | G11: 0 | H11: 113 | I11: 9 | J11: 6 | K11: =IF(OR(CLIENTS__3[[#This Row],[Duree_Cumulee_Panne_Min]]>=240,CLIENTS__3[[#This Row],[Plaintes_Service_Client]]>2),"45%",IF(CLIENTS__3[[#This Row],[Anciennete_Mois]]>=60,"10%",IF(CLIENTS__3[[#This Row],[Type_Forfait]]="Premium 5G 150 Go","70%","0%"))) -> 45% | L11: =(CLIENTS__3[[#This Row],[Facture_Mensuelle]]*CLIENTS__3[[#This Row],[ Remise client]]) -> 5.4495 | M11: =IF(CLIENTS__3[[#This Row],[Facture_Mensuelle]]<80,"B2B","B2C") -> B2B
A12: CLI-00060 | B12: Kasai-Central | C12: 72 | D12: Pro Monde | E12: 160 | F12: 90.13 | G12: 2 | H12: 72 | I12: 6 | J12: 3 | K12: =IF(OR(CLIENTS__3[[#This Row],[Duree_Cumulee_Panne_Min]]>=240,CLIENTS__3[[#This Row],[Plaintes_Service_Client]]>2),"45%",IF(CLIENTS__3[[#This Row],[Anciennete_Mois]]>=60,"10%",IF(CLIENTS__3[[#This Row],[Type_Forfait]]="Premium 5G 150 Go","70%","0%"))) -> 10% | L12: =(CLIENTS__3[[#This Row],[Facture_Mensuelle]]*CLIENTS__3[[#This Row],[ Remise client]]) -> 9.013 | M12: =IF(CLIENTS__3[[#This Row],[Facture_Mensuelle]]<80,"B2B","B2C") -> B2C
A13: CLI-00530 | B13: Sankuru | C13: 35 | D13: Pro Monde | E13: 465 | F13: 58.59 | G13: 5 | H13: 35 | I13: 3 | J13: 8 | K13: =IF(OR(CLIENTS__3[[#This Row],[Duree_Cumulee_Panne_Min]]>=240,CLIENTS__3[[#This Row],[Plaintes_Service_Client]]>2),"45%",IF(CLIENTS__3[[#This Row],[Anciennete_Mois]]>=60,"10%",IF(CLIENTS__3[[#This Row],[Type_Forfait]]="Premium 5G 150 Go","70%","0%"))) -> 45% | L13: =(CLIENTS__3[[#This Row],[Facture_Mensuelle]]*CLIENTS__3[[#This Row],[ Remise client]]) -> 26.3655 | M13: =IF(CLIENTS__3[[#This Row],[Facture_Mensuelle]]<80,"B2B","B2C") -> B2B
... A190: CLI-01689 | B190: Kasai-Central | C190: 55 | D190: Premium 5G 150Go | E190: 394 | F190: 26.8 | G190: 4 | H190: 55 | I190: 5 | J190: 7 | K190: =IF(OR(CLIENTS__3[[#This Row],[Duree_Cumulee_Panne_Min]]>=240,CLIENTS__3[[#This Row],[Plaintes_Service_Client]]>2),"45%",IF(CLIENTS__3[[#This Row],[Anciennete_Mois]]>=60,"10%",IF(CLIENTS__3[[#This Row],[Type_Forfait]]="Premium 5G 150 Go","70%","0%"))) -> 45% | L190: =(CLIENTS__3[[#This Row],[Facture_Mensuelle]]*CLIENTS__3[[#This Row],[ Remise client]]) -> 12.06 | M190: =IF(CLIENTS__3[[#This Row],[Facture_Mensuelle]]<80,"B2B","B2C") -> B2B
A191: CLI-01839 | B191: Haut-Lomami | C191: 114 | D191: Premium 5G 150Go | E191: 482 | F191: 16.25 | G191: 3 | H191: 114 | I191: 10 | J191: 8 | K191: =IF(OR(CLIENTS__3[[#This Row],[Duree_Cumulee_Panne_Min]]>=240,CLIENTS__3[[#This Row],[Plaintes_Service_Client]]>2),"45%",IF(CLIENTS__3[[#This Row],[Anciennete_Mois]]>=60,"10%",IF(CLIENTS__3[[#This Row],[Type_Forfait]]="Premium 5G 150 Go","70%","0%"))) -> 45% | L191: =F174*K174 -> 39.6135 | M191: =IF(CLIENTS__3[[#This Row],[Facture_Mensuelle]]<80,"B2B","B2C") -> B2B
A192: CLI-01431 | B192: Kwango | C192: 49 | D192: Premium 5G 150Go | E192: 357 | F192: 96.67 | G192: 3 | H192: 49 | I192: 4 | J192: 6 | K192: =IF(OR(CLIENTS__3[[#This Row],[Duree_Cumulee_Panne_Min]]>=240,CLIENTS__3[[#This Row],[Plaintes_Service_Client]]>2),"45%",IF(CLIENTS__3[[#This Row],[Anciennete_Mois]]>=60,"10%",IF(CLIENTS__3[[#This Row],[Type_Forfait]]="Premium 5G 150 Go","70%","0%"))) -> 45% | L192: =F175*K175 -> 44.199 | M192: =IF(CLIENTS__3[[#This Row],[Facture_Mensuelle]]<80,"B2B","B2C") -> B2C
A193: CLI-00535 | B193: Haut-Katanga | C193: 74 | D193: Premium 5G 150Go | E193: 213 | F193: 35.54 | G193: 3 | H193: 74 | I193: 6 | J193: 4 | K193: =IF(OR(CLIENTS__3[[#This Row],[Duree_Cumulee_Panne_Min]]>=240,CLIENTS__3[[#This Row],[Plaintes_Service_Client]]>2),"45%",IF(CLIENTS__3[[#This Row],[Anciennete_Mois]]>=60,"10%",IF(CLIENTS__3[[#This Row],[Type_Forfait]]="Premium 5G 150 Go","70%","0%"))) -> 45% | L193: =F176*K176 -> 12.771 | M193: =IF(CLIENTS__3[[#This Row],[Facture_Mensuelle]]<80,"B2B","B2C") -> B2B
A194: CLI-01037 | B194: Bas-Uele | C194: 21 | D194: Illimité 50Go | E194: 107 | F194: 30.97 | G194: 4 | H194: 21 | I194: 2 | J194: 2 | K194: =IF(OR(CLIENTS__3[[#This Row],[Duree_Cumulee_Panne_Min]]>=240,CLIENTS__3[[#This Row],[Plaintes_Service_Client]]>2),"45%",IF(CLIENTS__3[[#This Row],[Anciennete_Mois]]>=60,"10%",IF(CLIENTS__3[[#This Row],[Type_Forfait]]="Premium 5G 150 Go","70%","0%"))) -> 45% | L194: =F177*K177 -> 20.322 | M194: =IF(CLIENTS__3[[#This Row],[Facture_Mensuelle]]<80,"B2B","B2C") -> B2B
A195: CLI-00136 | B195: Haut-Katanga | C195: 120 | D195: Illimité 50Go | E195: 224 | F195: 69.36 | G195: 0 | H195: 120 | I195: 10 | J195: 4 | K195: =IF(OR(CLIENTS__3[[#This Row],[Duree_Cumulee_Panne_Min]]>=240,CLIENTS__3[[#This Row],[Plaintes_Service_Client]]>2),"45%",IF(CLIENTS__3[[#This Row],[Anciennete_Mois]]>=60,"10%",IF(CLIENTS__3[[#This Row],[Type_Forfait]]="Premium 5G 150 Go","70%","0%"))) -> 10% | L195: =F178*K178 -> 26.145 | M195: =IF(CLIENTS__3[[#This Row],[Facture_Mensuelle]]<80,"B2B","B2C") -> B2B
A196: CLI-00721 | B196: Tshuapa | C196: 108 | D196: Premium 5G 150Go | E196: 230 | F196: 16.3 | G196: 5 | H196: 108 | I196: 9 | J196: 4 | K196: =IF(OR(CLIENTS__3[[#This Row],[Duree_Cumulee_Panne_Min]]>=240,CLIENTS__3[[#This Row],[Plaintes_Service_Client]]>2),"45%",IF(CLIENTS__3[[#This Row],[Anciennete_Mois]]>=60,"10%",IF(CLIENTS__3[[#This Row],[Type_Forfait]]="Premium 5G 150 Go","70%","0%"))) -> 45% | L196: =F179*K179 -> 0 | M196: =IF(CLIENTS__3[[#This Row],[Facture_Mensuelle]]<80,"B2B","B2C") -> B2B
A197: CLI-00862 | B197: Sud-Ubangi | C197: 48 | D197: Bloqué 5Go | E197: 436 | F197: 15.17 | G197: 0 | H197: 48 | I197: 4 | J197: 7 | K197: =IF(OR(CLIENTS__3[[#This Row],[Duree_Cumulee_Panne_Min]]>=240,CLIENTS__3[[#This Row],[Plaintes_Service_Client]]>2),"45%",IF(CLIENTS__3[[#This Row],[Anciennete_Mois]]>=60,"10%",IF(CLIENTS__3[[#This Row],[Type_Forfait]]="Premium 5G 150 Go","70%","0%"))) -> 45% | L197: =F180*K180 -> 8.901 | M197: =IF(CLIENTS__3[[#This Row],[Facture_Mensuelle]]<80,"B2B","B2C") -> B2B
A198: CLI-01234 | B198: Kwango | C198: 33 | D198: Premium 5G 150Go | E198: 285 | F198: 56.67 | G198: 2 | H198: 33 | I198: 3 | J198: 5 | K198: =IF(OR(CLIENTS__3[[#This Row],[Duree_Cumulee_Panne_Min]]>=240,CLIENTS__3[[#This Row],[Plaintes_Service_Client]]>2),"45%",IF(CLIENTS__3[[#This Row],[Anciennete_Mois]]>=60,"10%",IF(CLIENTS__3[[#This Row],[Type_Forfait]]="Premium 5G 150 Go","70%","0%"))) -> 45% | L198: =F181*K181 -> 27.567 | M198: =IF(CLIENTS__3[[#This Row],[Facture_Mensuelle]]<80,"B2B","B2C") -> B2B
A199: CLI-01494 | B199: Kasai | C199: 71 | D199: Premium 5G 150Go | E199: 15 | F199: 25.46 | G199: 5 | H199: 71 | I199: 6 | J199: 0 | K199: =IF(OR(CLIENTS__3[[#This Row],[Duree_Cumulee_Panne_Min]]>=240,CLIENTS__3[[#This Row],[Plaintes_Service_Client]]>2),"45%",IF(CLIENTS__3[[#This Row],[Anciennete_Mois]]>=60,"10%",IF(CLIENTS__3[[#This Row],[Type_Forfait]]="Premium 5G 150 Go","70%","0%"))) -> 45% | L199: =F182*K182 -> 5.064 | M199: =IF(CLIENTS__3[[#This Row],[Facture_Mensuelle]]<80,"B2B","B2C") -> B2B
A200: CLI-01666 | B200: Tshopo | C200: 11 | D200: Premium 5G 150Go | E200: 191 | F200: 87.37 | G200: 3 | H200: 11 | I200: 1 | J200: 3 | K200: =IF(OR(CLIENTS__3[[#This Row],[Duree_Cumulee_Panne_Min]]>=240,CLIENTS__3[[#This Row],[Plaintes_Service_Client]]>2),"45%",IF(CLIENTS__3[[#This Row],[Anciennete_Mois]]>=60,"10%",IF(CLIENTS__3[[#This Row],[Type_Forfait]]="Premium 5G 150 Go","70%","0%"))) -> 45% | L200: =F183*K183 -> 40.7385 | M200: =IF(CLIENTS__3[[#This Row],[Facture_Mensuelle]]<80,"B2B","B2C") -> B2C
A201: CLI-01122 | B201: Nord-Kivu | C201: 18 | D201: Pro Monde | E201: 71 | F201: 46.98 | G201: 2 | H201: 18 | I201: 2 | J201: 1 | K201: =IF(OR(CLIENTS__3[[#This Row],[Duree_Cumulee_Panne_Min]]>=240,CLIENTS__3[[#This Row],[Plaintes_Service_Client]]>2),"45%",IF(CLIENTS__3[[#This Row],[Anciennete_Mois]]>=60,"10%",IF(CLIENTS__3[[#This Row],[Type_Forfait]]="Premium 5G 150 Go","70%","0%"))) -> 0% | L201: =F184*K184 -> 8.2755 | M201: =IF(CLIENTS__3[[#This Row],[Facture_Mensuelle]]<80,"B2B","B2C") -> B2B
A202: CLI-01511 | B202: Sankuru | C202: 27 | D202: Premium 5G 150Go | E202: 61 | F202: 97.51 | G202: 5 | H202: 27 | I202: 2 | J202: 1 | K202: =IF(OR(CLIENTS__3[[#This Row],[Duree_Cumulee_Panne_Min]]>=240,CLIENTS__3[[#This Row],[Plaintes_Service_Client]]>2),"45%",IF(CLIENTS__3[[#This Row],[Anciennete_Mois]]>=60,"10%",IF(CLIENTS__3[[#This Row],[Type_Forfait]]="Premium 5G 150 Go","70%","0%"))) -> 45% | L202: =F185*K185 -> 8.7255 | M202: =IF(CLIENTS__3[[#This Row],[Facture_Mensuelle]]<80,"B2B","B2C") -> B2C
... A751: CLI-00800 | B751: Nord-Kivu | C751: 4 | D751: Bloqué 5Go | E751: 21 | F751: 45.8 | G751: 1 | H751: 4 | I751: 0 | J751: 0 | K751: =IF(OR(CLIENTS__3[[#This Row],[Duree_Cumulee_Panne_Min]]>=240,CLIENTS__3[[#This Row],[Plaintes_Service_Client]]>2),"45%",IF(CLIENTS__3[[#This Row],[Anciennete_Mois]]>=60,"10%",IF(CLIENTS__3[[#This Row],[Type_Forfait]]="Premium 5G 150 Go","70%","0%"))) -> 0% | L751: =F734*K734 -> 21.231 | M751: =IF(CLIENTS__3[[#This Row],[Facture_Mensuelle]]<80,"B2B","B2C") -> B2B

Sheet maintenance
A1: ID_Antenne | B1: Province_RDC | C1: Latitude | D1: Longitude | E1: Technologie | F1: Equipementier
A2: ANT-0001 | B2: Nord-Ubangi | C2: -8.143791 | D2: 28.946161 | E2: 4G | F2: ZTE
A3: ANT-0002 | B3: Mai-Ndombe | C3: -10.442425 | D3: 23.243632 | E3: 4G | F3: Nokia
A4: ANT-0005 | B4: Equateur | C4: -3.544581 | D4: 14.776605 | E4: 4G | F4: Nokia
A5: ANT-0006 | B5: Bas-Uele | C5: -2.853287 | D5: 22.117896 | E5: 5G | F5: Huawei
A6: ANT-0007 | B6: Tshopo | C6: 4.777735 | D6: 16.392204 | E6: 5G | F6: ZTE
A7: ANT-0008 | B7: Haut-Lomami | C7: -11.89448 | D7: 19.216215 | E7: 3G | F7: ZTE
A8: ANT-0010 | B8: Haut-Katanga | C8: 4.471256 | D8: 27.107028 | E8: 3G | F8: Ericsson
A9: ANT-0011 | B9: Mai-Ndombe | C9: -1.607639 | D9: 17.003636 | E9: 4G | F9: Ericsson
A10: ANT-0016 | B10: Kongo-Central | C10: 2.983602 | D10: 21.893065 | E10: 5G | F10: Nokia
A11: ANT-0017 | B11: Sankuru | C11: -3.419035 | D11: 29.018316 | E11: 5G | F11: Ericsson
A12: ANT-0020 | B12: Kasai | C12: -10.059846 | D12: 14.375758 | E12: 4G | F12: Huawei
A13: ANT-0023 | B13: Haut-Lomami | C13: -9.780186 | D13: 16.64955 | E13: 5G | F13: Ericsson
... A74: ANT-0159 | B74: Sud-Kivu | C74: 2.441451 | D74: 30.167489 | E74: 5G | F74: Nokia
A75: ANT-0160 | C75: -8.487583 | D75: 19.436312 | E75: 5G | F75: Huawei
A76: ANT-0162 | B76: Kasai-Oriental | C76: -1.648326 | D76: 25.528902 | E76: 4G | F76: Huawei
A77: ANT-0164 | B77: Kinshasa | C77: -11.389362 | D77: 22.240174 | E77: 5G | F77: ZTE
A78: ANT-0165 | B78: Sud-Ubangi | C78: -0.549086 | D78: 14.816867 | E78: 5G | F78: ZTE
A79: ANT-0166 | B79: Sud-Ubangi | C79: -10.56448 | D79: 19.792876 | E79: 5G | F79: Ericsson
A80: ANT-0170 | B80: Bas-Uele | C80: -12.244119 | D80: 28.279756 | E80: 5G | F80: ZTE
A81: ANT-0171 | B81: Kwilu | C81: -3.571288 | D81: 12.931596 | E81: 4G | F81: Nokia
A82: ANT-0172 | B82: Lualaba | C82: 2.266232 | D82: 29.532896 | E82: 4G | F82: Ericsson
A83: ANT-0174 | B83: Maniema | C83: 3.08182 | D83: 29.961941 | E83: 4G | F83: Huawei
A84: ANT-0175 | B84: Maniema | C84: 0.850665 | D84: 19.446418 | E84: 4G | F84: Huawei
A85: ANT-0178 | B85: Kasai | C85: 4.146449 | D85: 17.793337 | E85: 5G | F85: ZTE
A86: ANT-0179 | B86: Nord-Kivu | C86: 0.928852 | D86: 25.868548 | E86: 5G | F86: Nokia
A87: ANT-0180 | B87: Tshopo | C87: 2.442598 | D87: 24.924308 | E87: 5G | F87: Ericsson
... A301: ANT-0614 | B301: Tshopo | C301: -6.183785 | D301: 25.138759 | E301: 3G | F301: Ericsson
A302: ANT-0615 | C302: 3.979001 | D302: 28.069559 | E302: 3G | F302: Huawei
A303: ANT-0616 | B303: Equateur | C303: -3.709361 | D303: 23.959943 | E303: 4G | F303: Huawei
A304: ANT-0617 | B304: Tshuapa | C304: -7.758771 | D304: 17.880848 | E304: 3G | F304: Ericsson
A305: ANT-0618 | B305: Mongala | C305: -4.332408 | D305: 14.119439 | E305: 5G | F305: Nokia
A306: ANT-0619 | B306: Sankuru | C306: -7.513261 | D306: 24.338812 | E306: 5G | F306: Huawei
A307: ANT-0620 | B307: Nord-Kivu | C307: -4.175494 | D307: 16.704665 | E307: 3G | F307: Ericsson
A308: ANT-0621 | B308: Haut-Katanga | C308: -2.926736 | D308: 18.170461 | E308: 5G | F308: Ericsson
A309: ANT-0622 | B309: Haut-Uele | C309: -3.003879 | D309: 23.633893 | E309: 5G | F309: Ericsson
A310: ANT-0624 | B310: Haut-Katanga | C310: 0.172153 | D310: 21.091376 | E310: 3G | F310: Ericsson
A311: ANT-0625 | B311: Haut-Lomami | C311: 0.76493 | D311: 21.564275 | E311: 3G | F311: ZTE
A312: ANT-0627 | B312: Nord-Ubangi | C312: -11.472475 | D312: 27.4189 | E312: 4G | F312: ZTE
A313: ANT-0629 | B313: Kwango | C313: 1.204588 | D313: 15.525152 | E313: 5G | F313: Huawei
...

Sheet logs
A1: Cell_ID | B1: Nombre abonne | C1: total dure | D1: derniere heur
A2: ANT-0465 | B2: 2 | C2: 136 | D2: 45228.792
A3: ANT-0004 | B3: 3 | C3: 161 | D3: 45226.003
A4: ANT-0977 | B4: 2 | C4: 153 | D4: 45224.378
A5: ANT-0740 | B5: 2 | C5: 129 | D5: 45221.998
A6: ANT-0897 | B6: 3 | C6: 161 | D6: 45222.772
A7: ANT-0737 | B7: 5 | C7: 389 | D7: 45219.476
A8: ANT-0270 | B8: 2 | C8: 87 | D8: 45221.181
A9: ANT-0996 | B9: 2 | C9: 92 | D9: 45216.792
A10: ANT-0513 | B10: 1 | C10: 51 | D10: 45217.281
A11: ANT-0781 | B11: 2 | C11: 114 | D11: 45227.483
A12: ANT-0183 | B12: 2 | C12: 101 | D12: 45213.311
A13: ANT-0520 | B13: 2 | C13: 155 | D13: 45218.369
... A661: ANT-0241 | B661: 1 | C661: 33 | D661: 45212.721

Sheet TCD
B3: Étiquettes de colonnes
B4: Somme de Date_Heure_Panne | F4: Moyenne de Duree_Panne_Min | J4: Total Somme de Date_Heure_Panne | K4: Total Moyenne de Duree_Panne_Min
A5: Étiquettes de lignes | B5: 3G | C5: 4G | D5: 5G | E5: non | F5: 3G | G5: 4G | H5: 5G | I5: non
A6: 0 | B6: 45226.748 | F6: 68 | J6: 45226.748 | K6: 68
A7: Bas-Uele | B7: 497309.31 | C7: 768626.58 | D7: 633061.06 | F7: 55.454545 | G7: 74.235294 | H7: 61.785714 | J7: 1898996.9 | K7: 65.166667
A8: Equateur | B8: 633064.82 | C8: 361761.2 | D8: 633052.17 | F8: 60.642857 | G8: 49.875 | H8: 71.214286 | J8: 1627878.2 | K8: 62.361111
A9: Haut-Katanga | B9: 678204.47 | C9: 452145.23 | D9: 452121.91 | F9: 74.733333 | G9: 69.6 | H9: 84.9 | J9: 1582471.6 | K9: 76.171429
A10: Haut-Lomami | B10: 316532.47 | C10: 1039909.7 | D10: 135666.61 | F10: 60.285714 | G10: 60.956522 | H10: 80 | J10: 1492108.8 | K10: 62.545455
A11: Haut-Uele | B11: 271304.55 | C11: 542604.68 | D11: 994711.69 | F11: 55 | G11: 60 | H11: 63.863636 | J11: 1808620.9 | K11: 61.375
A12: Ituri | B12: 542573.36 | C12: 406903.43 | D12: 497368.42 | F12: 75.833333 | G12: 69.666667 | H12: 56.090909 | J12: 1446845.2 | K12: 67.3125
A13: Kasai | B13: 226071.02 | C13: 452131.42 | D13: 678206.93 | F13: 58 | G13: 55.1 | H13: 68.266667 | J13: 1356409.4 | K13: 62.166667
A14: Kasai-Central | B14: 723406.57 | C14: 406919.18 | D14: 406933.21 | F14: 56.9375 | G14: 54.222222 | H14: 46.777778 | J14: 1537259 | K14: 53.529412
A15: Kasai-Oriental | B15: 135643.71 | C15: 180865.66 | D15: 406955.48 | F15: 50.666667 | G15: 53.5 | H15: 62.666667 | J15: 723464.85 | K15: 58.125
A16: Kinshasa | B16: 542572.54 | C16: 135638.74 | D16: 723505.51 | F16: 67.25 | G16: 58 | H16: 57.375 | J16: 1401716.8 | K16: 61.258065
A17: Kongo-Central | B17: 180841.23 | C17: 632942.7 | D17: 1446842 | F17: 82.75 | G17: 58 | H17: 78.09375 | J17: 2260625.9 | K17: 72.84
A18: Kwango | B18: 135661.16 | C18: 587874.93 | D18: 452117.02 | F18: 46.333333 | G18: 59.384615 | H18: 56.6 | J18: 1175653.1 | K18: 56.807692
... A22: Mai-Ndombe | B22: 90431.658 | C22: 949496.69 | D22: 90453.402 | F22: 69.5 | G22: 48.333333 | H22: 44.5 | J22: 1130381.8 | K22: 49.72
A23: Maniema | C23: 1446872.2 | D23: 406941.53 | G23: 64.4375 | H23: 59.6 | J23: 1853813.8 | K23: 63.285714
A24: Mongala | B24: 452153.44 | C24: 135640.09 | D24: 406974.97 | F24: 71.4 | G24: 104.33333 | H24: 65.666667 | J24: 994768.5 | K24: 73.545455
A25: non | E25: 46210539 | I25: 63.476144 | J25: 46210539 | K25: 63.476144
A26: Nord-Kivu | B26: 994710.12 | C26: 542569.98 | D26: 1356451.2 | F26: 61.909091 | G26: 47 | H26: 57.333333 | J26: 2893731.3 | K26: 56.96875
A27: Nord-Ubangi | B27: 497358.3 | C27: 633056.42 | D27: 768720.43 | F27: 48.181818 | G27: 63.428571 | H27: 63.176471 | J27: 1899135.2 | K27: 59.333333
A28: Sankuru | B28: 361745.7 | C28: 406932.64 | D28: 316542.19 | F28: 65.5 | G28: 58.888889 | H28: 64.714286 | J28: 1085220.5 | K28: 62.791667
A29: Sud-Kivu | B29: 1672977.3 | C29: 180859.15 | D29: 542644.59 | F29: 66.756757 | G29: 51.25 | H29: 80 | J29: 2396481 | K29: 68.584906
A30: Sud-Ubangi | B30: 632960.58 | C30: 180868.75 | D30: 1356527.8 | F30: 64 | G30: 89.25 | H30: 59.833333 | J30: 2170357.1 | K30: 63.5
A31: Tanganyika | B31: 361760.9 | C31: 723418.34 | D31: 723444.77 | F31: 66.625 | G31: 65.25 | H31: 67.4375 | J31: 1808624 | K31: 66.4
A32: Tshopo | B32: 452113.1 | C32: 633094.24 | D32: 768707.86 | F32: 72.4 | G32: 72 | H32: 56.823529 | J32: 1853915.2 | K32: 65.804878
A33: Tshuapa | B33: 316490.32 | C33: 452148.99 | D33: 452190.73 | F33: 51.428571 | G33: 62.090909 | H33: 57.7 | J33: 1220830 | K33: 57.857143
A34: Total général | B34: 12072382 | C34: 14423516 | D34: 15102362 | E34: 46210539 | F34: 63.595506 | G34: 61.909375 | H34: 64.19403 | I34: 63.476144 | J34: 87808800 | K34: 63.358645

Sheet logs vs maitenance
A1: Date_Heure_Panne | B1: Cell_ID | C1: Duree_Panne_Min | D1: Statut_Resolution | E1: region | F1: Latitude | G1: Longitude | H1: Technologie | I1: Equipementier
A2: 45200.767 | B2: ANT-0002 | C2: 78 | D2: Résolu | E2: =IFERROR(VLOOKUP(mes_fichiers_excel[[#This Row],[Cell_ID]],maintenance!A:B,2,FALSE),"non") -> Mai-Ndombe | F2: =IFERROR(VLOOKUP(mes_fichiers_excel[[#This Row],[Cell_ID]],maintenance!A:C,3,FALSE),"non") -> -10.442425 | G2: =IFERROR(VLOOKUP(mes_fichiers_excel[[#This Row],[Cell_ID]],maintenance!A:D,4,FALSE),"non") -> 23.243632 | H2: =IFERROR(VLOOKUP(mes_fichiers_excel[[#This Row],[Cell_ID]],maintenance!A:E,5,FALSE),"non") -> 4G | I2: =IFERROR(VLOOKUP(mes_fichiers_excel[[#This Row],[Cell_ID]],maintenance!A:F,6,FALSE),"non") -> Nokia
A3: 45226.104 | B3: ANT-0002 | C3: 56 | D3: Résolu | E3: =IFERROR(VLOOKUP(mes_fichiers_excel[[#This Row],[Cell_ID]],maintenance!A:B,2,FALSE),"non") -> Mai-Ndombe | F3: =IFERROR(VLOOKUP(mes_fichiers_excel[[#This Row],[Cell_ID]],maintenance!A:C,3,FALSE),"non") -> -10.442425 | G3: =IFERROR(VLOOKUP(mes_fichiers_excel[[#This Row],[Cell_ID]],maintenance!A:D,4,FALSE),"non") -> 23.243632 | H3: =IFERROR(VLOOKUP(mes_fichiers_excel[[#This Row],[Cell_ID]],maintenance!A:E,5,FALSE),"non") -> 4G | I3: =IFERROR(VLOOKUP(mes_fichiers_excel[[#This Row],[Cell_ID]],maintenance!A:F,6,FALSE),"non") -> Nokia
A4: 45230.153 | B4: ANT-0002 | C4: 43 | D4: Non Résolu | E4: =IFERROR(VLOOKUP(mes_fichiers_excel[[#This Row],[Cell_ID]],maintenance!A:B,2,FALSE),"non") -> Mai-Ndombe | F4: =IFERROR(VLOOKUP(mes_fichiers_excel[[#This Row],[Cell_ID]],maintenance!A:C,3,FALSE),"non") -> -10.442425 | G4: =IFERROR(VLOOKUP(mes_fichiers_excel[[#This Row],[Cell_ID]],maintenance!A:D,4,FALSE),"non") -> 23.243632 | H4: =IFERROR(VLOOKUP(mes_fichiers_excel[[#This Row],[Cell_ID]],maintenance!A:E,5,FALSE),"non") -> 4G | I4: =IFERROR(VLOOKUP(mes_fichiers_excel[[#This Row],[Cell_ID]],maintenance!A:F,6,FALSE),"non") -> Nokia
A5: 45207.525 | B5: ANT-0002 | C5: 104 | D5: Résolu | E5: =IFERROR(VLOOKUP(mes_fichiers_excel[[#This Row],[Cell_ID]],maintenance!A:B,2,FALSE),"non") -> Mai-Ndombe | F5: =IFERROR(VLOOKUP(mes_fichiers_excel[[#This Row],[Cell_ID]],maintenance!A:C,3,FALSE),"non") -> -10.442425 | G5: =IFERROR(VLOOKUP(mes_fichiers_excel[[#This Row],[Cell_ID]],maintenance!A:D,4,FALSE),"non") -> 23.243632 | H5: =IFERROR(VLOOKUP(mes_fichiers_excel[[#This Row],[Cell_ID]],maintenance!A:E,5,FALSE),"non") -> 4G | I5: =IFERROR(VLOOKUP(mes_fichiers_excel[[#This Row],[Cell_ID]],maintenance!A:F,6,FALSE),"non") -> Nokia
A6: 45204.296 | B6: ANT-0002 | C6: 48 | D6: En Cours | E6: =IFERROR(VLOOKUP(mes_fichiers_excel[[#This Row],[Cell_ID]],maintenance!A:B,2,FALSE),"non") -> Mai-Ndombe | F6: =IFERROR(VLOOKUP(mes_fichiers_excel[[#This Row],[Cell_ID]],maintenance!A:C,3,FALSE),"non") -> -10.442425 | G6: =IFERROR(VLOOKUP(mes_fichiers_excel[[#This Row],[Cell_ID]],maintenance!A:D,4,FALSE),"non") -> 23.243632 | H6: =IFERROR(VLOOKUP(mes_fichiers_excel[[#This Row],[Cell_ID]],maintenance!A:E,5,FALSE),"non") -> 4G | I6: =IFERROR(VLOOKUP(mes_fichiers_excel[[#This Row],[Cell_ID]],maintenance!A:F,6,FALSE),"non") -> Nokia
A7: 45224.568 | B7: ANT-0002 | C7: 27 | D7: Résolu | E7: =IFERROR(VLOOKUP(mes_fichiers_excel[[#This Row],[Cell_ID]],maintenance!A:B,2,FALSE),"non") -> Mai-Ndombe | F7: =IFERROR(VLOOKUP(mes_fichiers_excel[[#This Row],[Cell_ID]],maintenance!A:C,3,FALSE),"non") -> -10.442425 | G7: =IFERROR(VLOOKUP(mes_fichiers_excel[[#This Row],[Cell_ID]],maintenance!A:D,4,FALSE),"non") -> 23.243632 | H7: =IFERROR(VLOOKUP(mes_fichiers_excel[[#This Row],[Cell_ID]],maintenance!A:E,5,FALSE),"non") -> 4G | I7: =IFERROR(VLOOKUP(mes_fichiers_excel[[#This Row],[Cell_ID]],maintenance!A:F,6,FALSE),"non") -> Nokia
A8: 45210.742 | B8: ANT-0007 | C8: 19 | D8: Résolu | E8: =IFERROR(VLOOKUP(mes_fichiers_excel[[#This Row],[Cell_ID]],maintenance!A:B,2,FALSE),"non") -> Tshopo | F8: =IFERROR(VLOOKUP(mes_fichiers_excel[[#This Row],[Cell_ID]],maintenance!A:C,3,FALSE),"non") -> 4.777735 | G8: =IFERROR(VLOOKUP(mes_fichiers_excel[[#This Row],[Cell_ID]],maintenance!A:D,4,FALSE),"non") -> 16.392204 | H8: =IFERROR(VLOOKUP(mes_fichiers_excel[[#This Row],[Cell_ID]],maintenance!A:E,5,FALSE),"non") -> 5G | I8: =IFERROR(VLOOKUP(mes_fichiers_excel[[#This Row],[Cell_ID]],maintenance!A:F,6,FALSE),"non") -> ZTE
A9: 45226.624 | B9: ANT-0007 | C9: 103 | D9: Résolu | E9: =IFERROR(VLOOKUP(mes_fichiers_excel[[#This Row],[Cell_ID]],maintenance!A:B,2,FALSE),"non") -> Tshopo | F9: =IFERROR(VLOOKUP(mes_fichiers_excel[[#This Row],[Cell_ID]],maintenance!A:C,3,FALSE),"non") -> 4.777735 | G9: =IFERROR(VLOOKUP(mes_fichiers_excel[[#This Row],[Cell_ID]],maintenance!A:D,4,FALSE),"non") -> 16.392204 | H9: =IFERROR(VLOOKUP(mes_fichiers_excel[[#This Row],[Cell_ID]],maintenance!A:E,5,FALSE),"non") -> 5G | I9: =IFERROR(VLOOKUP(mes_fichiers_excel[[#This Row],[Cell_ID]],maintenance!A:F,6,FALSE),"non") -> ZTE
A10: 45207.14 | B10: ANT-0007 | C10: 41 | D10: Résolu | E10: =IFERROR(VLOOKUP(mes_fichiers_excel[[#This Row],[Cell_ID]],maintenance!A:B,2,FALSE),"non") -> Tshopo | F10: =IFERROR(VLOOKUP(mes_fichiers_excel[[#This Row],[Cell_ID]],maintenance!A:C,3,FALSE),"non") -> 4.777735 | G10: =IFERROR(VLOOKUP(mes_fichiers_excel[[#This Row],[Cell_ID]],maintenance!A:D,4,FALSE),"non") -> 16.392204 | H10: =IFERROR(VLOOKUP(mes_fichiers_excel[[#This Row],[Cell_ID]],maintenance!A:E,5,FALSE),"non") -> 5G | I10: =IFERROR(VLOOKUP(mes_fichiers_excel[[#This Row],[Cell_ID]],maintenance!A:F,6,FALSE),"non") -> ZTE
A11: 45221.566 | B11: ANT-0007 | C11: 87 | D11: Non Résolu | E11: =IFERROR(VLOOKUP(mes_fichiers_excel[[#This Row],[Cell_ID]],maintenance!A:B,2,FALSE),"non") -> Tshopo | F11: =IFERROR(VLOOKUP(mes_fichiers_excel[[#This Row],[Cell_ID]],maintenance!A:C,3,FALSE),"non") -> 4.777735 | G11: =IFERROR(VLOOKUP(mes_fichiers_excel[[#This Row],[Cell_ID]],maintenance!A:D,4,FALSE),"non") -> 16.392204 | H11: =IFERROR(VLOOKUP(mes_fichiers_excel[[#This Row],[Cell_ID]],maintenance!A:E,5,FALSE),"non") -> 5G | I11: =IFERROR(VLOOKUP(mes_fichiers_excel[[#This Row],[Cell_ID]],maintenance!A:F,6,FALSE),"non") -> ZTE
A12: 45210.803 | B12: ANT-0008 | C12: 52 | D12: Non Résolu | E12: =IFERROR(VLOOKUP(mes_fichiers_excel[[#This Row],[Cell_ID]],maintenance!A:B,2,FALSE),"non") -> Haut-Lomami | F12: =IFERROR(VLOOKUP(mes_fichiers_excel[[#This Row],[Cell_ID]],maintenance!A:C,3,FALSE),"non") -> -11.89448 | G12: =IFERROR(VLOOKUP(mes_fichiers_excel[[#This Row],[Cell_ID]],maintenance!A:D,4,FALSE),"non") -> 19.216215 | H12: =IFERROR(VLOOKUP(mes_fichiers_excel[[#This Row],[Cell_ID]],maintenance!A:E,5,FALSE),"non") -> 3G | I12: =IFERROR(VLOOKUP(mes_fichiers_excel[[#This Row],[Cell_ID]],maintenance!A:F,6,FALSE),"non") -> ZTE
A13: 45216.101 | B13: ANT-0008 | C13: 98 | D13: Non Résolu | E13: =IFERROR(VLOOKUP(mes_fichiers_excel[[#This Row],[Cell_ID]],maintenance!A:B,2,FALSE),"non") -> Haut-Lomami | F13: =IFERROR(VLOOKUP(mes_fichiers_excel[[#This Row],[Cell_ID]],maintenance!A:C,3,FALSE),"non") -> -11.89448 | G13: =IFERROR(VLOOKUP(mes_fichiers_excel[[#This Row],[Cell_ID]],maintenance!A:D,4,FALSE),"non") -> 19.216215 | H13: =IFERROR(VLOOKUP(mes_fichiers_excel[[#This Row],[Cell_ID]],maintenance!A:E,5,FALSE),"non") -> 3G | I13: =IFERROR(VLOOKUP(mes_fichiers_excel[[#This Row],[Cell_ID]],maintenance!A:F,6,FALSE),"non") -> ZTE
... A87: 45221.517 | B87: ANT-0046 | C87: 115 | D87: Résolu | E87: =IFERROR(VLOOKUP(mes_fichiers_excel[[#This Row],[Cell_ID]],maintenance!A:B,2,FALSE),"non") -> non | F87: =IFERROR(VLOOKUP(mes_fichiers_excel[[#This Row],[Cell_ID]],maintenance!A:C,3,FALSE),"non") -> non | G87: =IFERROR(VLOOKUP(mes_fichiers_excel[[#This Row],[Cell_ID]],maintenance!A:D,4,FALSE),"non") -> non | H87: =IFERROR(VLOOKUP(mes_fichiers_excel[[#This Row],[Cell_ID]],maintenance!A:E,5,FALSE),"non") -> non | I87: =IFERROR(VLOOKUP(mes_fichiers_excel[[#This Row],[Cell_ID]],maintenance!A:F,6,FALSE),"non") -> non
A88: 10/10/2023 15:30 | B88: ANT-0046 | C88: 112 | D88: En Cours | E88: =IFERROR(VLOOKUP(mes_fichiers_excel[[#This Row],[Cell_ID]],maintenance!A:B,2,FALSE),"non") -> non | F88: =IFERROR(VLOOKUP(mes_fichiers_excel[[#This Row],[Cell_ID]],maintenance!A:C,3,FALSE),"non") -> non | G88: =IFERROR(VLOOKUP(mes_fichiers_excel[[#This Row],[Cell_ID]],maintenance!A:D,4,FALSE),"non") -> non | H88: =IFERROR(VLOOKUP(mes_fichiers_excel[[#This Row],[Cell_ID]],maintenance!A:E,5,FALSE),"non") -> non | I88: =IFERROR(VLOOKUP(mes_fichiers_excel[[#This Row],[Cell_ID]],maintenance!A:F,6,FALSE),"non") -> non
A89: 45202.389 | B89: ANT-0046 | C89: 27 | D89: Résolu | E89: =IFERROR(VLOOKUP(mes_fichiers_excel[[#This Row],[Cell_ID]],maintenance!A:B,2,FALSE),"non") -> non | F89: =IFERROR(VLOOKUP(mes_fichiers_excel[[#This Row],[Cell_ID]],maintenance!A:C,3,FALSE),"non") -> non | G89: =IFERROR(VLOOKUP(mes_fichiers_excel[[#This Row],[Cell_ID]],maintenance!A:D,4,FALSE),"non") -> non | H89: =IFERROR(VLOOKUP(mes_fichiers_excel[[#This Row],[Cell_ID]],maintenance!A:E,5,FALSE),"non") -> non | I89: =IFERROR(VLOOKUP(mes_fichiers_excel[[#This Row],[Cell_ID]],maintenance!A:F,6,FALSE),"non") -> non
A90: 45217.322 | B90: ANT-0046 | C90: 59 | D90: En Cours | E90: =IFERROR(VLOOKUP(mes_fichiers_excel[[#This Row],[Cell_ID]],maintenance!A:B,2,FALSE),"non") -> non | F90: =IFERROR(VLOOKUP(mes_fichiers_excel[[#This Row],[Cell_ID]],maintenance!A:C,3,FALSE),"non") -> non | G90: =IFERROR(VLOOKUP(mes_fichiers_excel[[#This Row],[Cell_ID]],maintenance!A:D,4,FALSE),"non") -> non | H90: =IFERROR(VLOOKUP(mes_fichiers_excel[[#This Row],[Cell_ID]],maintenance!A:E,5,FALSE),"non") -> non | I90: =IFERROR(VLOOKUP(mes_fichiers_excel[[#This Row],[Cell_ID]],maintenance!A:F,6,FALSE),"non") -> non
A91: 45201.857 | B91: ANT-0046 | C91: 61 | D91: Résolu | E91: =IFERROR(VLOOKUP(mes_fichiers_excel[[#This Row],[Cell_ID]],maintenance!A:B,2,FALSE),"non") -> non | F91: =IFERROR(VLOOKUP(mes_fichiers_excel[[#This Row],[Cell_ID]],maintenance!A:C,3,FALSE),"non") -> non | G91: =IFERROR(VLOOKUP(mes_fichiers_excel[[#This Row],[Cell_ID]],maintenance!A:D,4,FALSE),"non") -> non | H91: =IFERROR(VLOOKUP(mes_fichiers_excel[[#This Row],[Cell_ID]],maintenance!A:E,5,FALSE),"non") -> non | I91: =IFERROR(VLOOKUP(mes_fichiers_excel[[#This Row],[Cell_ID]],maintenance!A:F,6,FALSE),"non") -> non
A92: 45225.16 | B92: ANT-0050 | C92: 56 | D92: Non Résolu | E92: =IFERROR(VLOOKUP(mes_fichiers_excel[[#This Row],[Cell_ID]],maintenance!A:B,2,FALSE),"non") -> non | F92: =IFERROR(VLOOKUP(mes_fichiers_excel[[#This Row],[Cell_ID]],maintenance!A:C,3,FALSE),"non") -> non | G92: =IFERROR(VLOOKUP(mes_fichiers_excel[[#This Row],[Cell_ID]],maintenance!A:D,4,FALSE),"non") -> non | H92: =IFERROR(VLOOKUP(mes_fichiers_excel[[#This Row],[Cell_ID]],maintenance!A:E,5,FALSE),"non") -> non | I92: =IFERROR(VLOOKUP(mes_fichiers_excel[[#This Row],[Cell_ID]],maintenance!A:F,6,FALSE),"non") -> non
A93: 45227.335 | B93: ANT-0050 | C93: 90 | D93: Non Résolu | E93: =IFERROR(VLOOKUP(mes_fichiers_excel[[#This Row],[Cell_ID]],maintenance!A:B,2,FALSE),"non") -> non | F93: =IFERROR(VLOOKUP(mes_fichiers_excel[[#This Row],[Cell_ID]],maintenance!A:C,3,FALSE),"non") -> non | G93: =IFERROR(VLOOKUP(mes_fichiers_excel[[#This Row],[Cell_ID]],maintenance!A:D,4,FALSE),"non") -> non | H93: =IFERROR(VLOOKUP(mes_fichiers_excel[[#This Row],[Cell_ID]],maintenance!A:E,5,FALSE),"non") -> non | I93: =IFERROR(VLOOKUP(mes_fichiers_excel[[#This Row],[Cell_ID]],maintenance!A:F,6,FALSE),"non") -> non
A94: 45227.335 | B94: ANT-0050 | C94: 90 | D94: Non Résolu | E94: =IFERROR(VLOOKUP(mes_fichiers_excel[[#This Row],[Cell_ID]],maintenance!A:B,2,FALSE),"non") -> non | F94: =IFERROR(VLOOKUP(mes_fichiers_excel[[#This Row],[Cell_ID]],maintenance!A:C,3,FALSE),"non") -> non | G94: =IFERROR(VLOOKUP(mes_fichiers_excel[[#This Row],[Cell_ID]],maintenance!A:D,4,FALSE),"non") -> non | H94: =IFERROR(VLOOKUP(mes_fichiers_excel[[#This Row],[Cell_ID]],maintenance!A:E,5,FALSE),"non") -> non | I94: =IFERROR(VLOOKUP(mes_fichiers_excel[[#This Row],[Cell_ID]],maintenance!A:F,6,FALSE),"non") -> non
A95: 45211.324 | B95: ANT-0050 | C95: 120 | D95: En Cours | E95: =IFERROR(VLOOKUP(mes_fichiers_excel[[#This Row],[Cell_ID]],maintenance!A:B,2,FALSE),"non") -> non | F95: =IFERROR(VLOOKUP(mes_fichiers_excel[[#This Row],[Cell_ID]],maintenance!A:C,3,FALSE),"non") -> non | G95: =IFERROR(VLOOKUP(mes_fichiers_excel[[#This Row],[Cell_ID]],maintenance!A:D,4,FALSE),"non") -> non | H95: =IFERROR(VLOOKUP(mes_fichiers_excel[[#This Row],[Cell_ID]],maintenance!A:E,5,FALSE),"non") -> non | I95: =IFERROR(VLOOKUP(mes_fichiers_excel[[#This Row],[Cell_ID]],maintenance!A:F,6,FALSE),"non") -> non
A96: 45222.426 | B96: ANT-0058 | C96: 74 | D96: Résolu | E96: =IFERROR(VLOOKUP(mes_fichiers_excel[[#This Row],[Cell_ID]],maintenance!A:B,2,FALSE),"non") -> Tshopo | F96: =IFERROR(VLOOKUP(mes_fichiers_excel[[#This Row],[Cell_ID]],maintenance!A:C,3,FALSE),"non") -> -6.467019 | G96: =IFERROR(VLOOKUP(mes_fichiers_excel[[#This Row],[Cell_ID]],maintenance!A:D,4,FALSE),"non") -> 29.487309 | H96: =IFERROR(VLOOKUP(mes_fichiers_excel[[#This Row],[Cell_ID]],maintenance!A:E,5,FALSE),"non") -> 4G | I96: =IFERROR(VLOOKUP(mes_fichiers_excel[[#This Row],[Cell_ID]],maintenance!A:F,6,FALSE),"non") -> ZTE
A97: 45216.458 | B97: ANT-0058 | C97: 27 | D97: Résolu | E97: =IFERROR(VLOOKUP(mes_fichiers_excel[[#This Row],[Cell_ID]],maintenance!A:B,2,FALSE),"non") -> Tshopo | F97: =IFERROR(VLOOKUP(mes_fichiers_excel[[#This Row],[Cell_ID]],maintenance!A:C,3,FALSE),"non") -> -6.467019 | G97: =IFERROR(VLOOKUP(mes_fichiers_excel[[#This Row],[Cell_ID]],maintenance!A:D,4,FALSE),"non") -> 29.487309 | H97: =IFERROR(VLOOKUP(mes_fichiers_excel[[#This Row],[Cell_ID]],maintenance!A:E,5,FALSE),"non") -> 4G | I97: =IFERROR(VLOOKUP(mes_fichiers_excel[[#This Row],[Cell_ID]],maintenance!A:F,6,FALSE),"non") -> ZTE
A98: 45226.984 | B98: ANT-0058 | C98: 23 | D98: En Cours | E98: =IFERROR(VLOOKUP(mes_fichiers_excel[[#This Row],[Cell_ID]],maintenance!A:B,2,FALSE),"non") -> Tshopo | F98: =IFERROR(VLOOKUP(mes_fichiers_excel[[#This Row],[Cell_ID]],maintenance!A:C,3,FALSE),"non") -> -6.467019 | G98: =IFERROR(VLOOKUP(mes_fichiers_excel[[#This Row],[Cell_ID]],maintenance!A:D,4,FALSE),"non") -> 29.487309 | H98: =IFERROR(VLOOKUP(mes_fichiers_excel[[#This Row],[Cell_ID]],maintenance!A:E,5,FALSE),"non") -> 4G | I98: =IFERROR(VLOOKUP(mes_fichiers_excel[[#This Row],[Cell_ID]],maintenance!A:F,6,FALSE),"non") -> ZTE
A99: 45202.011 | B99: ANT-0058 | C99: 120 | D99: Non Résolu | E99: =IFERROR(VLOOKUP(mes_fichiers_excel[[#This Row],[Cell_ID]],maintenance!A:B,2,FALSE),"non") -> Tshopo | F99: =IFERROR(VLOOKUP(mes_fichiers_excel[[#This Row],[Cell_ID]],maintenance!A:C,3,FALSE),"non") -> -6.467019 | G99: =IFERROR(VLOOKUP(mes_fichiers_excel[[#This Row],[Cell_ID]],maintenance!A:D,4,FALSE),"non") -> 29.487309 | H99: =IFERROR(VLOOKUP(mes_fichiers_excel[[#This Row],[Cell_ID]],maintenance!A:E,5,FALSE),"non") -> 4G | I99: =IFERROR(VLOOKUP(mes_fichiers_excel[[#This Row],[Cell_ID]],maintenance!A:F,6,FALSE),"non") -> ZTE
A100: 45220.677 | B100: ANT-0058 | C100: 107 | D100: En Cours | E100: =IFERROR(VLOOKUP(mes_fichiers_excel[[#This Row],[Cell_ID]],maintenance!A:B,2,FALSE),"non") -> Tshopo | F100: =IFERROR(VLOOKUP(mes_fichiers_excel[[#This Row],[Cell_ID]],maintenance!A:C,3,FALSE),"non") -> -6.467019 | G100: =IFERROR(VLOOKUP(mes_fichiers_excel[[#This Row],[Cell_ID]],maintenance!A:D,4,FALSE),"non") -> 29.487309 | H100: =IFERROR(VLOOKUP(mes_fichiers_excel[[#This Row],[Cell_ID]],maintenance!A:E,5,FALSE),"non") -> 4G | I100: =IFERROR(VLOOKUP(mes_fichiers_excel[[#This Row],[Cell_ID]],maintenance!A:F,6,FALSE),"non") -> ZTE
... A155: 45228.758 | B155: ANT-0079 | C155: 71 | D155: Non Résolu | E155: =IFERROR(VLOOKUP(mes_fichiers_excel[[#This Row],[Cell_ID]],maintenance!A:B,2,FALSE),"non") -> Maniema | F155: =IFERROR(VLOOKUP(mes_fichiers_excel[[#This Row],[Cell_ID]],maintenance!A:C,3,FALSE),"non") -> -8.482467 | G155: =IFERROR(VLOOKUP(mes_fichiers_excel[[#This Row],[Cell_ID]],maintenance!A:D,4,FALSE),"non") -> 21.897778 | H155: =IFERROR(VLOOKUP(mes_fichiers_excel[[#This Row],[Cell_ID]],maintenance!A:E,5,FALSE),"non") -> 5G | I155: =IFERROR(VLOOKUP(mes_fichiers_excel[[#This Row],[Cell_ID]],maintenance!A:F,6,FALSE),"non") -> Ericsson
A156: 27/10/2023 04:31 | B156: ANT-0079 | C156: 80 | D156: En Cours | E156: =IFERROR(VLOOKUP(mes_fichiers_excel[[#This Row],[Cell_ID]],maintenance!A:B,2,FALSE),"non") -> Maniema | F156: =IFERROR(VLOOKUP(mes_fichiers_excel[[#This Row],[Cell_ID]],maintenance!A:C,3,FALSE),"non") -> -8.482467 | G156: =IFERROR(VLOOKUP(mes_fichiers_excel[[#This Row],[Cell_ID]],maintenance!A:D,4,FALSE),"non") -> 21.897778 | H156: =IFERROR(VLOOKUP(mes_fichiers_excel[[#This Row],[Cell_ID]],maintenance!A:E,5,FALSE),"non") -> 5G | I156: =IFERROR(VLOOKUP(mes_fichiers_excel[[#This Row],[Cell_ID]],maintenance!A:F,6,FALSE),"non") -> Ericsson
A157: 45219.92 | B157: ANT-0079 | C157: 90 | D157: Résolu | E157: =IFERROR(VLOOKUP(mes_fichiers_excel[[#This Row],[Cell_ID]],maintenance!A:B,2,FALSE),"non") -> Maniema | F157: =IFERROR(VLOOKUP(mes_fichiers_excel[[#This Row],[Cell_ID]],maintenance!A:C,3,FALSE),"non") -> -8.482467 | G157: =IFERROR(VLOOKUP(mes_fichiers_excel[[#This Row],[Cell_ID]],maintenance!A:D,4,FALSE),"non") -> 21.897778 | H157: =IFERROR(VLOOKUP(mes_fichiers_excel[[#This Row],[Cell_ID]],maintenance!A:E,5,FALSE),"non") -> 5G | I157: =IFERROR(VLOOKUP(mes_fichiers_excel[[#This Row],[Cell_ID]],maintenance!A:F,6,FALSE),"non") -> Ericsson
A158: 45221.376 | B158: ANT-0079 | C158: 59 | D158: En Cours | E158: =IFERROR(VLOOKUP(mes_fichiers_excel[[#This Row],[Cell_ID]],maintenance!A:B,2,FALSE),"non") -> Maniema | F158: =IFERROR(VLOOKUP(mes_fichiers_excel[[#This Row],[Cell_ID]],maintenance!A:C,3,FALSE),"non") -> -8.482467 | G158: =IFERROR(VLOOKUP(mes_fichiers_excel[[#This Row],[Cell_ID]],maintenance!A:D,4,FALSE),"non") -> 21.897778 | H158: =IFERROR(VLOOKUP(mes_fichiers_excel[[#This Row],[Cell_ID]],maintenance!A:E,5,FALSE),"non") -> 5G | I158: =IFERROR(VLOOKUP(mes_fichiers_excel[[#This Row],[Cell_ID]],maintenance!A:F,6,FALSE),"non") -> Ericsson
A159: 45210.458 | B159: ANT-0080 | C159: 73 | D159: Non Résolu | E159: =IFERROR(VLOOKUP(mes_fichiers_excel[[#This Row],[Cell_ID]],maintenance!A:B,2,FALSE),"non") -> Ituri | F159: =IFERROR(VLOOKUP(mes_fichiers_excel[[#This Row],[Cell_ID]],maintenance!A:C,3,FALSE),"non") -> 0.24202 | G159: =IFERROR(VLOOKUP(mes_fichiers_excel[[#This Row],[Cell_ID]],maintenance!A:D,4,FALSE),"non") -> 17.396257 | H159: =IFERROR(VLOOKUP(mes_fichiers_excel[[#This Row],[Cell_ID]],maintenance!A:E,5,FALSE),"non") -> 4G | I159: =IFERROR(VLOOKUP(mes_fichiers_excel[[#This Row],[Cell_ID]],maintenance!A:F,6,FALSE),"non") -> Huawei
A160: 45206.167 | B160: ANT-0080 | C160: 64 | D160: Non Résolu | E160: =IFERROR(VLOOKUP(mes_fichiers_excel[[#This Row],[Cell_ID]],maintenance!A:B,2,FALSE),"non") -> Ituri | F160: =IFERROR(VLOOKUP(mes_fichiers_excel[[#This Row],[Cell_ID]],maintenance!A:C,3,FALSE),"non") -> 0.24202 | G160: =IFERROR(VLOOKUP(mes_fichiers_excel[[#This Row],[Cell_ID]],maintenance!A:D,4,FALSE),"non") -> 17.396257 | H160: =IFERROR(VLOOKUP(mes_fichiers_excel[[#This Row],[Cell_ID]],maintenance!A:E,5,FALSE),"non") -> 4G | I160: =IFERROR(VLOOKUP(mes_fichiers_excel[[#This Row],[Cell_ID]],maintenance!A:F,6,FALSE),"non") -> Huawei
A161: 45223.208 | B161: ANT-0086 | C161: 107 | D161: Non Résolu | E161: =IFERROR(VLOOKUP(mes_fichiers_excel[[#This Row],[Cell_ID]],maintenance!A:B,2,FALSE),"non") -> Sud-Kivu | F161: =IFERROR(VLOOKUP(mes_fichiers_excel[[#This Row],[Cell_ID]],maintenance!A:C,3,FALSE),"non") -> 4.290463 | G161: =IFERROR(VLOOKUP(mes_fichiers_excel[[#This Row],[Cell_ID]],maintenance!A:D,4,FALSE),"non") -> 26.354195 | H161: =IFERROR(VLOOKUP(mes_fichiers_excel[[#This Row],[Cell_ID]],maintenance!A:E,5,FALSE),"non") -> 3G | I161: =IFERROR(VLOOKUP(mes_fichiers_excel[[#This Row],[Cell_ID]],maintenance!A:F,6,FALSE),"non") -> Ericsson
A162: 45222.376 | B162: ANT-0086 | C162: 65 | D162: En Cours | E162: =IFERROR(VLOOKUP(mes_fichiers_excel[[#This Row],[Cell_ID]],maintenance!A:B,2,FALSE),"non") -> Sud-Kivu | F162: =IFERROR(VLOOKUP(mes_fichiers_excel[[#This Row],[Cell_ID]],maintenance!A:C,3,FALSE),"non") -> 4.290463 | G162: =IFERROR(VLOOKUP(mes_fichiers_excel[[#This Row],[Cell_ID]],maintenance!A:D,4,FALSE),"non") -> 26.354195 | H162: =IFERROR(VLOOKUP(mes_fichiers_excel[[#This Row],[Cell_ID]],maintenance!A:E,5,FALSE),"non") -> 3G | I162: =IFERROR(VLOOKUP(mes_fichiers_excel[[#This Row],[Cell_ID]],maintenance!A:F,6,FALSE),"non") -> Ericsson
A163: 45219.98 | B163: ANT-0086 | C163: 12 | D163: En Cours | E163: =IFERROR(VLOOKUP(mes_fichiers_excel[[#This Row],[Cell_ID]],maintenance!A:B,2,FALSE),"non") -> Sud-Kivu | F163: =IFERROR(VLOOKUP(mes_fichiers_excel[[#This Row],[Cell_ID]],maintenance!A:C,3,FALSE),"non") -> 4.290463 | G163: =IFERROR(VLOOKUP(mes_fichiers_excel[[#This Row],[Cell_ID]],maintenance!A:D,4,FALSE),"non") -> 26.354195 | H163: =IFERROR(VLOOKUP(mes_fichiers_excel[[#This Row],[Cell_ID]],maintenance!A:E,5,FALSE),"non") -> 3G | I163: =IFERROR(VLOOKUP(mes_fichiers_excel[[#This Row],[Cell_ID]],maintenance!A:F,6,FALSE),"non") -> Ericsson
A164: 45225.147 | B164: ANT-0086 | C164: 44 | D164: Résolu | E164: =IFERROR(VLOOKUP(mes_fichiers_excel[[#This Row],[Cell_ID]],maintenance!A:B,2,FALSE),"non") -> Sud-Kivu | F164: =IFERROR(VLOOKUP(mes_fichiers_excel[[#This Row],[Cell_ID]],maintenance!A:C,3,FALSE),"non") -> 4.290463 | G164: =IFERROR(VLOOKUP(mes_fichiers_excel[[#This Row],[Cell_ID]],maintenance!A:D,4,FALSE),"non") -> 26.354195 | H164: =IFERROR(VLOOKUP(mes_fichiers_excel[[#This Row],[Cell_ID]],maintenance!A:E,5,FALSE),"non") -> 3G | I164: =IFERROR(VLOOKUP(mes_fichiers_excel[[#This Row],[Cell_ID]],maintenance!A:F,6,FALSE),"non") -> Ericsson
A165: 45213.299 | B165: ANT-0087 | C165: 43 | D165: En Cours | E165: =IFERROR(VLOOKUP(mes_fichiers_excel[[#This Row],[Cell_ID]],maintenance!A:B,2,FALSE),"non") -> non | F165: =IFERROR(VLOOKUP(mes_fichiers_excel[[#This Row],[Cell_ID]],maintenance!A:C,3,FALSE),"non") -> non | G165: =IFERROR(VLOOKUP(mes_fichiers_excel[[#This Row],[Cell_ID]],maintenance!A:D,4,FALSE),"non") -> non | H165: =IFERROR(VLOOKUP(mes_fichiers_excel[[#This Row],[Cell_ID]],maintenance!A:E,5,FALSE),"non") -> non | I165: =IFERROR(VLOOKUP(mes_fichiers_excel[[#This Row],[Cell_ID]],maintenance!A:F,6,FALSE),"non") -> non
A166: 45203.324 | B166: ANT-0087 | C166: 34 | D166: Résolu | E166: =IFERROR(VLOOKUP(mes_fichiers_excel[[#This Row],[Cell_ID]],maintenance!A:B,2,FALSE),"non") -> non | F166: =IFERROR(VLOOKUP(mes_fichiers_excel[[#This Row],[Cell_ID]],maintenance!A:C,3,FALSE),"non") -> non | G166: =IFERROR(VLOOKUP(mes_fichiers_excel[[#This Row],[Cell_ID]],maintenance!A:D,4,FALSE),"non") -> non | H166: =IFERROR(VLOOKUP(mes_fichiers_excel[[#This Row],[Cell_ID]],maintenance!A:E,5,FALSE),"non") -> non | I166: =IFERROR(VLOOKUP(mes_fichiers_excel[[#This Row],[Cell_ID]],maintenance!A:F,6,FALSE),"non") -> non
A167: 45205.6 | B167: ANT-0090 | C167: 15 | D167: En Cours | E167: =IFERROR(VLOOKUP(mes_fichiers_excel[[#This Row],[Cell_ID]],maintenance!A:B,2,FALSE),"non") -> Kasai-Central | F167: =IFERROR(VLOOKUP(mes_fichiers_excel[[#This Row],[Cell_ID]],maintenance!A:C,3,FALSE),"non") -> -7.337934 | G167: =IFERROR(VLOOKUP(mes_fichiers_excel[[#This Row],[Cell_ID]],maintenance!A:D,4,FALSE),"non") -> 28.404002 | H167: =IFERROR(VLOOKUP(mes_fichiers_excel[[#This Row],[Cell_ID]],maintenance!A:E,5,FALSE),"non") -> 3G | I167: =IFERROR(VLOOKUP(mes_fichiers_excel[[#This Row],[Cell_ID]],maintenance!A:F,6,FALSE),"non") -> Nokia
...
